Workbook

Sheet Dashboard
A1: =Setup!$B$3&" | Budget vs Actual Tracker" -> [Client Name] | Budget vs Actual Tracker
A3: ="FY"&YEAR(Setup!$B$5)&" | Actuals through "&TEXT(Setup!$B$6,"mmm yyyy") -> FY2026 | Actuals through Jul 2026 | F3: ="Currency: "&Setup!$B$4 -> Currency: USD | I3: ="Version "&Setup!$B$8&" | "&Setup!$B$7 -> Version v1.0 | Finance Team
A5: YTD Budget | D5: YTD Actual | G5: YTD Variance | J5: Variance %
A6: =SUMIFS('Data Entry'!$E$8:$E$127,'Data Entry'!$A$8:$A$127,"<="&Setup!$B$6) -> 3238060 | D6: =SUMIFS('Data Entry'!$F$8:$F$127,'Data Entry'!$A$8:$A$127,"<="&Setup!$B$6) -> 3260383 | G6: =A6-D6 -> -22323 | J6: =IFERROR(G6/A6,"") -> -0.0068939427
A10: Category Variance | Year-to-Date | B10: Category Variance | Year-to-Date | C10: Category Variance | Year-to-Date | D10: Category Variance | Year-to-Date | E10: Category Variance | Year-to-Date | G10: Management Attention | H10: Management Attention | I10: Management Attention | J10: Management Attention | K10: Management Attention | L10: Management Attention
A11: Category | B11: Budget ($) | C11: Actual ($) | D11: Variance ($) | E11: Variance % | G11: Metric | K11: Value
A12: Payroll | B12: =SUMIFS('Data Entry'!$E$8:$E$127,'Data Entry'!$A$8:$A$127,"<="&Setup!$B$6,'Data Entry'!$C$8:$C$127,A12) -> 1414000 | C12: =SUMIFS('Data Entry'!$F$8:$F$127,'Data Entry'!$A$8:$A$127,"<="&Setup!$B$6,'Data Entry'!$C$8:$C$127,A12) -> 1416676 | D12: =B12-C12 -> -2676 | E12: =IFERROR(D12/B12,"") -> -0.0018925035 | G12: Over-budget categories | K12: =COUNTIF(D12:D19,"<0") -> 8
A13: Occupancy | B13: =SUMIFS('Data Entry'!$E$8:$E$127,'Data Entry'!$A$8:$A$127,"<="&Setup!$B$6,'Data Entry'!$C$8:$C$127,A13) -> 424200 | C13: =SUMIFS('Data Entry'!$F$8:$F$127,'Data Entry'!$A$8:$A$127,"<="&Setup!$B$6,'Data Entry'!$C$8:$C$127,A13) -> 427984 | D13: =B13-C13 -> -3784 | E13: =IFERROR(D13/B13,"") -> -0.0089203206 | G13: Largest unfavorable variance | K13: =MIN(D12:D19) -> -9063
A14: Marketing | B14: =SUMIFS('Data Entry'!$E$8:$E$127,'Data Entry'!$A$8:$A$127,"<="&Setup!$B$6,'Data Entry'!$C$8:$C$127,A14) -> 530250 | C14: =SUMIFS('Data Entry'!$F$8:$F$127,'Data Entry'!$A$8:$A$127,"<="&Setup!$B$6,'Data Entry'!$C$8:$C$127,A14) -> 539313 | D14: =B14-C14 -> -9063 | E14: =IFERROR(D14/B14,"") -> -0.017091938 | G14: Actuals loaded / expected | K14: =COUNTIFS('Data Entry'!$A$8:$A$127,"<>",'Data Entry'!$A$8:$A$127,"<="&Setup!$B$6,'Data Entry'!$F$8:$F$127,"<>")&" / "&COUNTIFS('Data Entry'!$A$8:$A$127,"<>",'Data Entry'!$A$8:$A$127,"<="&Setup!$B$6) -> 56 / 56
A15: Technology | B15: =SUMIFS('Data Entry'!$E$8:$E$127,'Data Entry'!$A$8:$A$127,"<="&Setup!$B$6,'Data Entry'!$C$8:$C$127,A15) -> 318150 | C15: =SUMIFS('Data Entry'!$F$8:$F$127,'Data Entry'!$A$8:$A$127,"<="&Setup!$B$6,'Data Entry'!$C$8:$C$127,A15) -> 318753 | D15: =B15-C15 -> -603 | E15: =IFERROR(D15/B15,"") -> -0.0018953324 | G15: Model status | K15: =Checks!$B$3 -> PASS
A16: Travel | B16: =SUMIFS('Data Entry'!$E$8:$E$127,'Data Entry'!$A$8:$A$127,"<="&Setup!$B$6,'Data Entry'!$C$8:$C$127,A16) -> 127260 | C16: =SUMIFS('Data Entry'!$F$8:$F$127,'Data Entry'!$A$8:$A$127,"<="&Setup!$B$6,'Data Entry'!$C$8:$C$127,A16) -> 128395 | D16: =B16-C16 -> -1135 | E16: =IFERROR(D16/B16,"") -> -0.008918749
A17: Professional Fees | B17: =SUMIFS('Data Entry'!$E$8:$E$127,'Data Entry'!$A$8:$A$127,"<="&Setup!$B$6,'Data Entry'!$C$8:$C$127,A17) -> 247450 | C17: =SUMIFS('Data Entry'!$F$8:$F$127,'Data Entry'!$A$8:$A$127,"<="&Setup!$B$6,'Data Entry'!$C$8:$C$127,A17) -> 251680 | D17: =B17-C17 -> -4230 | E17: =IFERROR(D17/B17,"") -> -0.017094362
A18: Office & Admin | B18: =SUMIFS('Data Entry'!$E$8:$E$127,'Data Entry'!$A$8:$A$127,"<="&Setup!$B$6,'Data Entry'!$C$8:$C$127,A18) -> 106050 | C18: =SUMIFS('Data Entry'!$F$8:$F$127,'Data Entry'!$A$8:$A$127,"<="&Setup!$B$6,'Data Entry'!$C$8:$C$127,A18) -> 106251 | D18: =B18-C18 -> -201 | E18: =IFERROR(D18/B18,"") -> -0.0018953324
A19: Other | B19: =SUMIFS('Data Entry'!$E$8:$E$127,'Data Entry'!$A$8:$A$127,"<="&Setup!$B$6,'Data Entry'!$C$8:$C$127,A19) -> 70700 | C19: =SUMIFS('Data Entry'!$F$8:$F$127,'Data Entry'!$A$8:$A$127,"<="&Setup!$B$6,'Data Entry'!$C$8:$C$127,A19) -> 71331 | D19: =B19-C19 -> -631 | E19: =IFERROR(D19/B19,"") -> -0.0089250354
A22: Monthly Budget vs Actual | Trend | B22: Monthly Budget vs Actual | Trend | C22: Monthly Budget vs Actual | Trend | D22: Monthly Budget vs Actual | Trend | E22: Monthly Budget vs Actual | Trend
A23: Month | B23: Budget ($) | C23: Actual ($) | D23: Variance ($) | E23: Variance %
A24: =TEXT(DATE(YEAR(Setup!$B$5),MONTH(Setup!$B$5)+ROW()-24,1),"mmm yyyy") -> Jan 2026 | B24: =SUMIFS('Data Entry'!$E$8:$E$127,'Data Entry'!$A$8:$A$127,DATE(YEAR(Setup!$B$5),MONTH(Setup!$B$5)+ROW()-24,1)) -> 458000 | C24: =IF(DATE(YEAR(Setup!$B$5),MONTH(Setup!$B$5)+ROW()-24,1)<=Setup!$B$6,SUMIFS('Data Entry'!$F$8:$F$127,'Data Entry'!$A$8:$A$127,DATE(YEAR(Setup!$B$5),MONTH(Setup!$B$5)+ROW()-24,1)),"") -> 447152 | D24: =IF(C24="","",B24-C24) -> 10848 | E24: =IFERROR(D24/B24,"") -> 0.02368559
A25: =TEXT(DATE(YEAR(Setup!$B$5),MONTH(Setup!$B$5)+ROW()-24,1),"mmm yyyy") -> Feb 2026 | B25: =SUMIFS('Data Entry'!$E$8:$E$127,'Data Entry'!$A$8:$A$127,DATE(YEAR(Setup!$B$5),MONTH(Setup!$B$5)+ROW()-24,1)) -> 448840 | C25: =IF(DATE(YEAR(Setup!$B$5),MONTH(Setup!$B$5)+ROW()-24,1)<=Setup!$B$6,SUMIFS('Data Entry'!$F$8:$F$127,'Data Entry'!$A$8:$A$127,DATE(YEAR(Setup!$B$5),MONTH(Setup!$B$5)+ROW()-24,1)),"") -> 461141 | D25: =IF(C25="","",B25-C25) -> -12301 | E25: =IFERROR(D25/B25,"") -> -0.027406203
A26: =TEXT(DATE(YEAR(Setup!$B$5),MONTH(Setup!$B$5)+ROW()-24,1),"mmm yyyy") -> Mar 2026 | B26: =SUMIFS('Data Entry'!$E$8:$E$127,'Data Entry'!$A$8:$A$127,DATE(YEAR(Setup!$B$5),MONTH(Setup!$B$5)+ROW()-24,1)) -> 471740 | C26: =IF(DATE(YEAR(Setup!$B$5),MONTH(Setup!$B$5)+ROW()-24,1)<=Setup!$B$6,SUMIFS('Data Entry'!$F$8:$F$127,'Data Entry'!$A$8:$A$127,DATE(YEAR(Setup!$B$5),MONTH(Setup!$B$5)+ROW()-24,1)),"") -> 469057 | D26: =IF(C26="","",B26-C26) -> 2683 | E26: =IFERROR(D26/B26,"") -> 0.005687455
A27: =TEXT(DATE(YEAR(Setup!$B$5),MONTH(Setup!$B$5)+ROW()-24,1),"mmm yyyy") -> Apr 2026 | B27: =SUMIFS('Data Entry'!$E$8:$E$127,'Data Entry'!$A$8:$A$127,DATE(YEAR(Setup!$B$5),MONTH(Setup!$B$5)+ROW()-24,1)) -> 462580 | C27: =IF(DATE(YEAR(Setup!$B$5),MONTH(Setup!$B$5)+ROW()-24,1)<=Setup!$B$6,SUMIFS('Data Entry'!$F$8:$F$127,'Data Entry'!$A$8:$A$127,DATE(YEAR(Setup!$B$5),MONTH(Setup!$B$5)+ROW()-24,1)),"") -> 469186 | D27: =IF(C27="","",B27-C27) -> -6606 | E27: =IFERROR(D27/B27,"") -> -0.014280773
A28: =TEXT(DATE(YEAR(Setup!$B$5),MONTH(Setup!$B$5)+ROW()-24,1),"mmm yyyy") -> May 2026 | B28: =SUMIFS('Data Entry'!$E$8:$E$127,'Data Entry'!$A$8:$A$127,DATE(YEAR(Setup!$B$5),MONTH(Setup!$B$5)+ROW()-24,1)) -> 453420 | C28: =IF(DATE(YEAR(Setup!$B$5),MONTH(Setup!$B$5)+ROW()-24,1)<=Setup!$B$6,SUMIFS('Data Entry'!$F$8:$F$127,'Data Entry'!$A$8:$A$127,DATE(YEAR(Setup!$B$5),MONTH(Setup!$B$5)+ROW()-24,1)),"") -> 459005 | D28: =IF(C28="","",B28-C28) -> -5585 | E28: =IFERROR(D28/B28,"") -> -0.012317498
A29: =TEXT(DATE(YEAR(Setup!$B$5),MONTH(Setup!$B$5)+ROW()-24,1),"mmm yyyy") -> Jun 2026 | B29: =SUMIFS('Data Entry'!$E$8:$E$127,'Data Entry'!$A$8:$A$127,DATE(YEAR(Setup!$B$5),MONTH(Setup!$B$5)+ROW()-24,1)) -> 476320 | C29: =IF(DATE(YEAR(Setup!$B$5),MONTH(Setup!$B$5)+ROW()-24,1)<=Setup!$B$6,SUMIFS('Data Entry'!$F$8:$F$127,'Data Entry'!$A$8:$A$127,DATE(YEAR(Setup!$B$5),MONTH(Setup!$B$5)+ROW()-24,1)),"") -> 491696 | D29: =IF(C29="","",B29-C29) -> -15376 | E29: =IFERROR(D29/B29,"") -> -0.03228082
A30: =TEXT(DATE(YEAR(Setup!$B$5),MONTH(Setup!$B$5)+ROW()-24,1),"mmm yyyy") -> Jul 2026 | B30: =SUMIFS('Data Entry'!$E$8:$E$127,'Data Entry'!$A$8:$A$127,DATE(YEAR(Setup!$B$5),MONTH(Setup!$B$5)+ROW()-24,1)) -> 467160 | C30: =IF(DATE(YEAR(Setup!$B$5),MONTH(Setup!$B$5)+ROW()-24,1)<=Setup!$B$6,SUMIFS('Data Entry'!$F$8:$F$127,'Data Entry'!$A$8:$A$127,DATE(YEAR(Setup!$B$5),MONTH(Setup!$B$5)+ROW()-24,1)),"") -> 463146 | D30: =IF(C30="","",B30-C30) -> 4014 | E30: =IFERROR(D30/B30,"") -> 0.0085923452
A31: =TEXT(DATE(YEAR(Setup!$B$5),MONTH(Setup!$B$5)+ROW()-24,1),"mmm yyyy") -> Aug 2026 | B31: =SUMIFS('Data Entry'!$E$8:$E$127,'Data Entry'!$A$8:$A$127,DATE(YEAR(Setup!$B$5),MONTH(Setup!$B$5)+ROW()-24,1)) -> 458000 | C31: =IF(DATE(YEAR(Setup!$B$5),MONTH(Setup!$B$5)+ROW()-24,1)<=Setup!$B$6,SUMIFS('Data Entry'!$F$8:$F$127,'Data Entry'!$A$8:$A$127,DATE(YEAR(Setup!$B$5),MONTH(Setup!$B$5)+ROW()-24,1)),"") | D31: =IF(C31="","",B31-C31) | E31: =IFERROR(D31/B31,"")
A32: =TEXT(DATE(YEAR(Setup!$B$5),MONTH(Setup!$B$5)+ROW()-24,1),"mmm yyyy") -> Sep 2026 | B32: =SUMIFS('Data Entry'!$E$8:$E$127,'Data Entry'!$A$8:$A$127,DATE(YEAR(Setup!$B$5),MONTH(Setup!$B$5)+ROW()-24,1)) -> 471740 | C32: =IF(DATE(YEAR(Setup!$B$5),MONTH(Setup!$B$5)+ROW()-24,1)<=Setup!$B$6,SUMIFS('Data Entry'!$F$8:$F$127,'Data Entry'!$A$8:$A$127,DATE(YEAR(Setup!$B$5),MONTH(Setup!$B$5)+ROW()-24,1)),"") | D32: =IF(C32="","",B32-C32) | E32: =IFERROR(D32/B32,"")
A33: =TEXT(DATE(YEAR(Setup!$B$5),MONTH(Setup!$B$5)+ROW()-24,1),"mmm yyyy") -> Oct 2026 | B33: =SUMIFS('Data Entry'!$E$8:$E$127,'Data Entry'!$A$8:$A$127,DATE(YEAR(Setup!$B$5),MONTH(Setup!$B$5)+ROW()-24,1)) -> 462580 | C33: =IF(DATE(YEAR(Setup!$B$5),MONTH(Setup!$B$5)+ROW()-24,1)<=Setup!$B$6,SUMIFS('Data Entry'!$F$8:$F$127,'Data Entry'!$A$8:$A$127,DATE(YEAR(Setup!$B$5),MONTH(Setup!$B$5)+ROW()-24,1)),"") | D33: =IF(C33="","",B33-C33) | E33: =IFERROR(D33/B33,"")
A34: =TEXT(DATE(YEAR(Setup!$B$5),MONTH(Setup!$B$5)+ROW()-24,1),"mmm yyyy") -> Nov 2026 | B34: =SUMIFS('Data Entry'!$E$8:$E$127,'Data Entry'!$A$8:$A$127,DATE(YEAR(Setup!$B$5),MONTH(Setup!$B$5)+ROW()-24,1)) -> 485480 | C34: =IF(DATE(YEAR(Setup!$B$5),MONTH(Setup!$B$5)+ROW()-24,1)<=Setup!$B$6,SUMIFS('Data Entry'!$F$8:$F$127,'Data Entry'!$A$8:$A$127,DATE(YEAR(Setup!$B$5),MONTH(Setup!$B$5)+ROW()-24,1)),"") | D34: =IF(C34="","",B34-C34) | E34: =IFERROR(D34/B34,"")
A35: =TEXT(DATE(YEAR(Setup!$B$5),MONTH(Setup!$B$5)+ROW()-24,1),"mmm yyyy") -> Dec 2026 | B35: =SUMIFS('Data Entry'!$E$8:$E$127,'Data Entry'!$A$8:$A$127,DATE(YEAR(Setup!$B$5),MONTH(Setup!$B$5)+ROW()-24,1)) -> 512960 | C35: =IF(DATE(YEAR(Setup!$B$5),MONTH(Setup!$B$5)+ROW()-24,1)<=Setup!$B$6,SUMIFS('Data Entry'!$F$8:$F$127,'Data Entry'!$A$8:$A$127,DATE(YEAR(Setup!$B$5),MONTH(Setup!$B$5)+ROW()-24,1)),"") | D35: =IF(C35="","",B35-C35) | E35: =IFERROR(D35/B35,"")
A36: Decision rule: For expense lines, a positive variance is favorable (actual spend is below budget). Review red cells before distribution.

Sheet Data Entry
A1: Budget vs Actual | Data Entry | B1: Budget vs Actual | Data Entry | C1: Budget vs Actual | Data Entry | D1: Budget vs Actual | Data Entry | E1: Budget vs Actual | Data Entry | F1: Budget vs Actual | Data Entry | G1: Budget vs Actual | Data Entry | H1: Budget vs Actual | Data Entry | I1: Budget vs Actual | Data Entry | J1: Budget vs Actual | Data Entry
A2: Budget vs Actual | Data Entry | B2: Budget vs Actual | Data Entry | C2: Budget vs Actual | Data Entry | D2: Budget vs Actual | Data Entry | E2: Budget vs Actual | Data Entry | F2: Budget vs Actual | Data Entry | G2: Budget vs Actual | Data Entry | H2: Budget vs Actual | Data Entry | I2: Budget vs Actual | Data Entry | J2: Budget vs Actual | Data Entry
A3: Replace the illustrative data before circulation. Pale yellow / blue text = editable input; black text = formula. All amounts are in the reporting currency.
A5: Expense variance convention: Budget − Actual. Positive variance is favorable; negative variance is an overspend.
A7: Month | B7: Department | C7: Category | D7: Cost Center | E7: Budget ($) | F7: Actual ($) | G7: Variance ($) | H7: Variance % | I7: Status | J7: Comment / Owner
A8: 46023 | B8: People | C8: Payroll | D8: PEO-001 | E8: 200000 | F8: 188000 | G8: =IF(OR(E8="",F8=""),"",E8-F8) -> 12000 | H8: =IFERROR(G8/E8,"") -> 0.06 | I8: =IF(A8="","",IF(F8="","Pending",IF(G8<0,"Over Budget","On / Under Budget"))) -> On / Under Budget | J8: Within plan | Finance
A9: 46023 | B9: Operations | C9: Occupancy | D9: OPE-001 | E9: 60000 | F9: 59640 | G9: =IF(OR(E9="",F9=""),"",E9-F9) -> 360 | H9: =IFERROR(G9/E9,"") -> 0.006 | I9: =IF(A9="","",IF(F9="","Pending",IF(G9<0,"Over Budget","On / Under Budget"))) -> On / Under Budget | J9: Within plan | Finance
A10: 46023 | B10: Marketing | C10: Marketing | D10: MAR-001 | E10: 75000 | F10: 78600 | G10: =IF(OR(E10="",F10=""),"",E10-F10) -> -3600 | H10: =IFERROR(G10/E10,"") -> -0.048 | I10: =IF(A10="","",IF(F10="","Pending",IF(G10<0,"Over Budget","On / Under Budget"))) -> Over Budget | J10: Investigate overspend | Finance
A11: 46023 | B11: Technology | C11: Technology | D11: TEC-001 | E11: 45000 | F11: 42300 | G11: =IF(OR(E11="",F11=""),"",E11-F11) -> 2700 | H11: =IFERROR(G11/E11,"") -> 0.06 | I11: =IF(A11="","",IF(F11="","Pending",IF(G11<0,"Over Budget","On / Under Budget"))) -> On / Under Budget | J11: Within plan | Finance
A12: 46023 | B12: Sales | C12: Travel | D12: SAL-001 | E12: 18000 | F12: 17892 | G12: =IF(OR(E12="",F12=""),"",E12-F12) -> 108 | H12: =IFERROR(G12/E12,"") -> 0.006 | I12: =IF(A12="","",IF(F12="","Pending",IF(G12<0,"Over Budget","On / Under Budget"))) -> On / Under Budget | J12: Within plan | Finance
A13: 46023 | B13: G&A | C13: Professional Fees | D13: G&A-001 | E13: 35000 | F13: 36680 | G13: =IF(OR(E13="",F13=""),"",E13-F13) -> -1680 | H13: =IFERROR(G13/E13,"") -> -0.048 | I13: =IF(A13="","",IF(F13="","Pending",IF(G13<0,"Over Budget","On / Under Budget"))) -> Over Budget | J13: Investigate overspend | Finance
A14: 46023 | B14: Operations | C14: Office & Admin | D14: OPE-001 | E14: 15000 | F14: 14100 | G14: =IF(OR(E14="",F14=""),"",E14-F14) -> 900 | H14: =IFERROR(G14/E14,"") -> 0.06 | I14: =IF(A14="","",IF(F14="","Pending",IF(G14<0,"Over Budget","On / Under Budget"))) -> On / Under Budget | J14: Within plan | Finance
A15: 46023 | B15: G&A | C15: Other | D15: G&A-001 | E15: 10000 | F15: 9940 | G15: =IF(OR(E15="",F15=""),"",E15-F15) -> 60 | H15: =IFERROR(G15/E15,"") -> 0.006 | I15: =IF(A15="","",IF(F15="","Pending",IF(G15<0,"Over Budget","On / Under Budget"))) -> On / Under Budget | J15: Within plan | Finance
A16: 46054 | B16: People | C16: Payroll | D16: PEO-001 | E16: 196000 | F16: 201880 | G16: =IF(OR(E16="",F16=""),"",E16-F16) -> -5880 | H16: =IFERROR(G16/E16,"") -> -0.03 | I16: =IF(A16="","",IF(F16="","Pending",IF(G16<0,"Over Budget","On / Under Budget"))) -> Over Budget | J16: Investigate overspend | Finance
A17: 46054 | B17: Operations | C17: Occupancy | D17: OPE-001 | E17: 58800 | F17: 63739 | G17: =IF(OR(E17="",F17=""),"",E17-F17) -> -4939 | H17: =IFERROR(G17/E17,"") -> -0.083996599 | I17: =IF(A17="","",IF(F17="","Pending",IF(G17<0,"Over Budget","On / Under Budget"))) -> Over Budget | J17: Investigate overspend | Finance
A18: 46054 | B18: Marketing | C18: Marketing | D18: MAR-001 | E18: 73500 | F18: 71736 | G18: =IF(OR(E18="",F18=""),"",E18-F18) -> 1764 | H18: =IFERROR(G18/E18,"") -> 0.024 | I18: =IF(A18="","",IF(F18="","Pending",IF(G18<0,"Over Budget","On / Under Budget"))) -> On / Under Budget | J18: Within plan | Finance
A19: 46054 | B19: Technology | C19: Technology | D19: TEC-001 | E19: 44100 | F19: 45423 | G19: =IF(OR(E19="",F19=""),"",E19-F19) -> -1323 | H19: =IFERROR(G19/E19,"") -> -0.03 | I19: =IF(A19="","",IF(F19="","Pending",IF(G19<0,"Over Budget","On / Under Budget"))) -> Over Budget | J19: Investigate overspend | Finance
... A63: 46204 | B63: G&A | C63: Other | D63: G&A-001 | E63: 10200 | F63: 10690 | G63: =IF(OR(E63="",F63=""),"",E63-F63) -> -490 | H63: =IFERROR(G63/E63,"") -> -0.048039216 | I63: =IF(A63="","",IF(F63="","Pending",IF(G63<0,"Over Budget","On / Under Budget"))) -> Over Budget | J63: Investigate overspend | Finance
A64: 46235 | B64: People | C64: Payroll | D64: PEO-001 | E64: 200000 | G64: =IF(OR(E64="",F64=""),"",E64-F64) | H64: =IFERROR(G64/E64,"") | I64: =IF(A64="","",IF(F64="","Pending",IF(G64<0,"Over Budget","On / Under Budget"))) -> Pending | J64: Awaiting actuals | Finance
A65: 46235 | B65: Operations | C65: Occupancy | D65: OPE-001 | E65: 60000 | G65: =IF(OR(E65="",F65=""),"",E65-F65) | H65: =IFERROR(G65/E65,"") | I65: =IF(A65="","",IF(F65="","Pending",IF(G65<0,"Over Budget","On / Under Budget"))) -> Pending | J65: Awaiting actuals | Finance
A66: 46235 | B66: Marketing | C66: Marketing | D66: MAR-001 | E66: 75000 | G66: =IF(OR(E66="",F66=""),"",E66-F66) | H66: =IFERROR(G66/E66,"") | I66: =IF(A66="","",IF(F66="","Pending",IF(G66<0,"Over Budget","On / Under Budget"))) -> Pending | J66: Awaiting actuals | Finance
A67: 46235 | B67: Technology | C67: Technology | D67: TEC-001 | E67: 45000 | G67: =IF(OR(E67="",F67=""),"",E67-F67) | H67: =IFERROR(G67/E67,"") | I67: =IF(A67="","",IF(F67="","Pending",IF(G67<0,"Over Budget","On / Under Budget"))) -> Pending | J67: Awaiting actuals | Finance
A68: 46235 | B68: Sales | C68: Travel | D68: SAL-001 | E68: 18000 | G68: =IF(OR(E68="",F68=""),"",E68-F68) | H68: =IFERROR(G68/E68,"") | I68: =IF(A68="","",IF(F68="","Pending",IF(G68<0,"Over Budget","On / Under Budget"))) -> Pending | J68: Awaiting actuals | Finance
A69: 46235 | B69: G&A | C69: Professional Fees | D69: G&A-001 | E69: 35000 | G69: =IF(OR(E69="",F69=""),"",E69-F69) | H69: =IFERROR(G69/E69,"") | I69: =IF(A69="","",IF(F69="","Pending",IF(G69<0,"Over Budget","On / Under Budget"))) -> Pending | J69: Awaiting actuals | Finance
A70: 46235 | B70: Operations | C70: Office & Admin | D70: OPE-001 | E70: 15000 | G70: =IF(OR(E70="",F70=""),"",E70-F70) | H70: =IFERROR(G70/E70,"") | I70: =IF(A70="","",IF(F70="","Pending",IF(G70<0,"Over Budget","On / Under Budget"))) -> Pending | J70: Awaiting actuals | Finance
A71: 46235 | B71: G&A | C71: Other | D71: G&A-001 | E71: 10000 | G71: =IF(OR(E71="",F71=""),"",E71-F71) | H71: =IFERROR(G71/E71,"") | I71: =IF(A71="","",IF(F71="","Pending",IF(G71<0,"Over Budget","On / Under Budget"))) -> Pending | J71: Awaiting actuals | Finance
A72: 46266 | B72: People | C72: Payroll | D72: PEO-001 | E72: 206000 | G72: =IF(OR(E72="",F72=""),"",E72-F72) | H72: =IFERROR(G72/E72,"") | I72: =IF(A72="","",IF(F72="","Pending",IF(G72<0,"Over Budget","On / Under Budget"))) -> Pending | J72: Awaiting actuals | Finance
A73: 46266 | B73: Operations | C73: Occupancy | D73: OPE-001 | E73: 61800 | G73: =IF(OR(E73="",F73=""),"",E73-F73) | H73: =IFERROR(G73/E73,"") | I73: =IF(A73="","",IF(F73="","Pending",IF(G73<0,"Over Budget","On / Under Budget"))) -> Pending | J73: Awaiting actuals | Finance
A74: 46266 | B74: Marketing | C74: Marketing | D74: MAR-001 | E74: 77250 | G74: =IF(OR(E74="",F74=""),"",E74-F74) | H74: =IFERROR(G74/E74,"") | I74: =IF(A74="","",IF(F74="","Pending",IF(G74<0,"Over Budget","On / Under Budget"))) -> Pending | J74: Awaiting actuals | Finance
A75: 46266 | B75: Technology | C75: Technology | D75: TEC-001 | E75: 46350 | G75: =IF(OR(E75="",F75=""),"",E75-F75) | H75: =IFERROR(G75/E75,"") | I75: =IF(A75="","",IF(F75="","Pending",IF(G75<0,"Over Budget","On / Under Budget"))) -> Pending | J75: Awaiting actuals | Finance
... A103: 46357 | B103: G&A | C103: Other | D103: G&A-001 | E103: 11200 | G103: =IF(OR(E103="",F103=""),"",E103-F103) | H103: =IFERROR(G103/E103,"") | I103: =IF(A103="","",IF(F103="","Pending",IF(G103<0,"Over Budget","On / Under Budget"))) -> Pending | J103: Awaiting actuals | Finance
G104: =IF(OR(E104="",F104=""),"",E104-F104) | H104: =IFERROR(G104/E104,"") | I104: =IF(A104="","",IF(F104="","Pending",IF(G104<0,"Over Budget","On / Under Budget")))
G105: =IF(OR(E105="",F105=""),"",E105-F105) | H105: =IFERROR(G105/E105,"") | I105: =IF(A105="","",IF(F105="","Pending",IF(G105<0,"Over Budget","On / Under Budget")))
G106: =IF(OR(E106="",F106=""),"",E106-F106) | H106: =IFERROR(G106/E106,"") | I106: =IF(A106="","",IF(F106="","Pending",IF(G106<0,"Over Budget","On / Under Budget")))
G107: =IF(OR(E107="",F107=""),"",E107-F107) | H107: =IFERROR(G107/E107,"") | I107: =IF(A107="","",IF(F107="","Pending",IF(G107<0,"Over Budget","On / Under Budget")))
G108: =IF(OR(E108="",F108=""),"",E108-F108) | H108: =IFERROR(G108/E108,"") | I108: =IF(A108="","",IF(F108="","Pending",IF(G108<0,"Over Budget","On / Under Budget")))
G109: =IF(OR(E109="",F109=""),"",E109-F109) | H109: =IFERROR(G109/E109,"") | I109: =IF(A109="","",IF(F109="","Pending",IF(G109<0,"Over Budget","On / Under Budget")))
G110: =IF(OR(E110="",F110=""),"",E110-F110) | H110: =IFERROR(G110/E110,"") | I110: =IF(A110="","",IF(F110="","Pending",IF(G110<0,"Over Budget","On / Under Budget")))
G111: =IF(OR(E111="",F111=""),"",E111-F111) | H111: =IFERROR(G111/E111,"") | I111: =IF(A111="","",IF(F111="","Pending",IF(G111<0,"Over Budget","On / Under Budget")))
G112: =IF(OR(E112="",F112=""),"",E112-F112) | H112: =IFERROR(G112/E112,"") | I112: =IF(A112="","",IF(F112="","Pending",IF(G112<0,"Over Budget","On / Under Budget")))
...

Sheet Setup
A1: Tracker Setup & Controls | B1: Tracker Setup & Controls | C1: Tracker Setup & Controls | D1: Tracker Setup & Controls | E1: Tracker Setup & Controls | F1: Tracker Setup & Controls | G1: Tracker Setup & Controls | H1: Tracker Setup & Controls
A2: Tracker Setup & Controls | B2: Tracker Setup & Controls | C2: Tracker Setup & Controls | D2: Tracker Setup & Controls | E2: Tracker Setup & Controls | F2: Tracker Setup & Controls | G2: Tracker Setup & Controls | H2: Tracker Setup & Controls
A3: Client / Entity Name | B3: [Client Name] | F3: Validation Lists | G3: Validation Lists | H3: Validation Lists
A4: Reporting Currency | B4: USD | F4: Departments | G4: Categories
A5: Fiscal Year Start | B5: 46023 | F5: People | G5: Payroll
A6: Actuals Through | B6: 46234 | F6: Operations | G6: Occupancy
A7: Prepared By | B7: Finance Team | F7: Marketing | G7: Marketing
A8: Version | B8: v1.0 | F8: Technology | G8: Technology
A9: Data Status | B9: Illustrative template — replace before circulation | F9: Sales | G9: Travel
F10: G&A | G10: Professional Fees
G11: Office & Admin
A12: Refresh Workflow | B12: Refresh Workflow | C12: Refresh Workflow | D12: Refresh Workflow | G12: Other
A13: 1. Update client details and reporting controls above.
A14: 2. Replace the illustrative, pale-yellow input rows in Data Entry with client actuals and approved budgets.
A15: 3. Use the first day of each month for every record and refresh the Actuals Through date.
A16: 4. Review Dashboard and Checks before sharing. Positive expense variance = favorable (spend below budget).

Sheet Checks
A1: Model Checks & Controls | B1: Model Checks & Controls | C1: Model Checks & Controls | D1: Model Checks & Controls | E1: Model Checks & Controls | F1: Model Checks & Controls
A2: Model Checks & Controls | B2: Model Checks & Controls | C2: Model Checks & Controls | D2: Model Checks & Controls | E2: Model Checks & Controls | F2: Model Checks & Controls
A3: MODEL STATUS | B3: =IF(COUNTIF(E7:E10,"FAIL")+COUNTIF(E7:E10,"CHECK")=0,"PASS","REVIEW") -> PASS
A5: Check | B5: Actual | C5: Expected | D5: Delta | E5: Status | F5: Where to Fix / Notes
A7: Budget entries populated | B7: =COUNT('Data Entry'!$E$8:$E$127) -> 96 | C7: =COUNT('Data Entry'!$A$8:$A$127) -> 96 | D7: =B7-C7 -> 0 | E7: =IF(D7=0,"PASS","FAIL") -> PASS | F7: Complete budget values for every active input row.
A8: Actual entries through reporting date | B8: =COUNTIFS('Data Entry'!$A$8:$A$127,"<="&Setup!$B$6,'Data Entry'!$F$8:$F$127,"<>") -> 56 | C8: =COUNTIFS('Data Entry'!$A$8:$A$127,"<>",'Data Entry'!$A$8:$A$127,"<="&Setup!$B$6) -> 56 | D8: =B8-C8 -> 0 | E8: =IF(D8=0,"PASS","CHECK") -> PASS | F8: Load all actuals dated on or before Actuals Through.
A9: Variance formulas complete | B9: =COUNT('Data Entry'!$G$8:$G$127) -> 56 | C9: =COUNTIFS('Data Entry'!$E$8:$E$127,">0",'Data Entry'!$F$8:$F$127,"<>") -> 56 | D9: =B9-C9 -> 0 | E9: =IF(D9=0,"PASS","FAIL") -> PASS | F9: Copy the formula columns when adding input rows outside the prepared table.
A10: Dashboard YTD tie-out | B10: =Dashboard!$A$6-Dashboard!$D$6 -> -22323 | C10: =SUMIFS('Data Entry'!$E$8:$E$127,'Data Entry'!$A$8:$A$127,"<="&Setup!$B$6)-SUMIFS('Data Entry'!$F$8:$F$127,'Data Entry'!$A$8:$A$127,"<="&Setup!$B$6) -> -22323 | D10: =B10-C10 -> 0 | E10: =IF(ABS(D10)<0.01,"PASS","FAIL") -> PASS | F10: Review Dashboard formulas and the Data Entry date range.

Sheet Read Me
A1: Budget vs Actual Tracker | Client Guide | B1: Budget vs Actual Tracker | Client Guide | C1: Budget vs Actual Tracker | Client Guide | D1: Budget vs Actual Tracker | Client Guide | E1: Budget vs Actual Tracker | Client Guide | F1: Budget vs Actual Tracker | Client Guide | G1: Budget vs Actual Tracker | Client Guide | H1: Budget vs Actual Tracker | Client Guide
A2: Budget vs Actual Tracker | Client Guide | B2: Budget vs Actual Tracker | Client Guide | C2: Budget vs Actual Tracker | Client Guide | D2: Budget vs Actual Tracker | Client Guide | E2: Budget vs Actual Tracker | Client Guide | F2: Budget vs Actual Tracker | Client Guide | G2: Budget vs Actual Tracker | Client Guide | H2: Budget vs Actual Tracker | Client Guide
A4: Purpose | B4: Purpose | C4: Purpose | D4: Purpose | E4: Purpose | F4: Purpose | G4: Purpose | H4: Purpose
A5: A client-ready monthly expense tracker with an executive dashboard, controlled data-entry area, visible data quality checks, and a clear favorable / unfavorable variance convention.
A8: Use It in Four Steps | B8: Use It in Four Steps | C8: Use It in Four Steps | D8: Use It in Four Steps | E8: Use It in Four Steps | F8: Use It in Four Steps | G8: Use It in Four Steps | H8: Use It in Four Steps
A9: 1 | B9: Update Client / Entity Name, currency, dates, preparer, and version on Setup.
A10: 2 | B10: Replace the illustrative Data Entry values with approved budgets and actual spending.
A11: 3 | B11: Set Actuals Through on Setup once the monthly close is complete.
A12: 4 | B12: Review Dashboard insights and confirm every control on Checks is PASS.
A14: Color Legend | B14: Color Legend | C14: Color Legend | D14: Color Legend | E14: Color Legend | F14: Color Legend | G14: Color Legend | H14: Color Legend
A15: Pale yellow / blue text | B15: Editable client inputs
A16: Black text | B16: Formulas and calculated outputs
A17: Green text | B17: References to other sheets in this workbook
A19: Variance Convention | B19: Variance Convention | C19: Variance Convention | D19: Variance Convention | E19: Variance Convention | F19: Variance Convention | G19: Variance Convention | H19: Variance Convention
A20: This tracker is configured for operating expenses: Variance = Budget − Actual. Positive values are favorable (spend below budget); negative values are unfavorable (spend above budget).
