Workbook
Name Slicer_Months__Date: #N/A
Name TblServices: #REF!

Sheet Settings
A1: Company Settings
A3: Company Name | B3: Shivam Analytics
A4: Owner Name | B4: Shivam Thakur
A5: Phone | B5: 9857050777
A6: Email | B6: shivamthakur32008@gmail.com
A7: Website
A8: GST Number
A9: Address | B9: SHIMLA
A10: Bank Name
A11: Account Name
A12: IFSC
A13: UPI
A14: Currency | B14: 0
A15: Tax Rate | B15: 0.18
A16: Invoice Prefix | B16: INV

Sheet client
A1: Client ID | B1: Client Name | C1: Contact Person | D1: Phone | E1: Email | F1: Address | G1: GST Number
A2: C0001 | B2: Summit Enterprises Technologies | C2: Harsh Sharma | D2: 9177777868 | E2: harsh.sharma@summit.in | F2: 106, Indore, MP | G2: 24ABCDE1950F1Z8
A3: C0002 | B3: Future Solutions LLP | C3: Deepak Mehta | D3: 9175006691 | E3: deepak.mehta@future.in | F3: 102, Hyderabad, TS | G3: 36ABCDE7955F1Z0
A4: C0003 | B4: Zenith Retail Pvt Ltd | C4: Ankit Yadav | D4: 9525932421 | E4: ankit.yadav@zenith.in | F4: 236, Mumbai, MH | G4: 03ABCDE3181F1Z4
A5: C0004 | B5: Vision Enterprises Enterprises | C5: Neha Yadav | D5: 9431229838 | E5: neha.yadav@vision.in | F5: 845, Indore, MP | G5: 12ABCDE2688F1Z9
A6: C0005 | B6: Golden Digital LLP | C6: Varun Mishra | D6: 9167419149 | E6: varun.mishra@golden.in | F6: 71, Surat, GJ | G6: 14ABCDE9133F1Z8
A7: C0006 | B7: Infinity Exports Works | C7: Riya Yadav | D7: 9586603020 | E7: riya.yadav@infinity.in | F7: 316, Ahmedabad, GJ | G7: 16ABCDE3945F1Z3
A8: C0007 | B8: Vertex Energy India | C8: Sneha Kapoor | D8: 9468804211 | E8: sneha.kapoor@vertex.in | F8: 469, Chennai, TN | G8: 19ABCDE2199F1Z1
A9: C0008 | B9: Matrix Manufacturing Corporation | C9: Suresh Gupta | D9: 9625020128 | E9: suresh.gupta@matrix.in | F9: 50, Jaipur, RJ | G9: 05ABCDE6140F1Z5
A10: C0009 | B10: Dynamic Packaging Solutions | C10: Ankit Reddy | D10: 9589846746 | E10: ankit.reddy@dynamic.in | F10: 870, Delhi, DL | G10: 06ABCDE5422F1Z7
A11: C0010 | B11: Elite Solutions India | C11: Harsh Yadav | D11: 9831472844 | E11: harsh.yadav@elite.in | F11: 301, Lucknow, UP | G11: 25ABCDE6685F1Z0
A12: C0011 | B12: Nexus Digital Corporation | C12: Divya Verma | D12: 9630098818 | E12: divya.verma@nexus.in | F12: 233, Mumbai, MH | G12: 19ABCDE3119F1Z3
A13: C0012 | B13: Rapid Healthcare Solutions | C13: Priya Gupta | D13: 9582311296 | E13: priya.gupta@rapid.in | F13: 572, Jaipur, RJ | G13: 18ABCDE3243F1Z6
... A401: C0400 | B401: NextGen Systems Corporation | C401: Aditya Patel | D401: 9654299835 | E401: aditya.patel@nextgen.in | F401: 486, Delhi, DL | G401: 07ABCDE4303F1Z1

Sheet Services
A1: Service ID | B1: Client ID | C1: Service Name | D1: Category | E1: Unit Price | F1: Unit
A2: S001 | B2: C0001 | C2: Sales Dashboard | D2: Dashboard | E2: 6000 | F2: Project
A3: S002 | B3: C0002 | C3: Finance Dashboard | D3: Dashboard | E3: 29500 | F3: Project
A4: S003 | B4: C0003 | C4: HR Dashboard | D4: Dashboard | E4: 17000 | F4: Project
A5: S004 | B5: C0004 | C5: Inventory Dashboard | D5: Dashboard | E5: 45000 | F5: Project
A6: S005 | B6: C0005 | C6: Marketing Dashboard | D6: Dashboard | E6: 19000 | F6: Project
A7: S006 | B7: C0006 | C7: Executive Dashboard | D7: Dashboard | E7: 48000 | F7: Project
A8: S007 | B8: C0007 | C8: KPI Dashboard | D8: Dashboard | E8: 31000 | F8: Project
A9: S008 | B9: C0008 | C9: Retail Dashboard | D9: Dashboard | E9: 46500 | F9: Project
A10: S009 | B10: C0009 | C10: Manufacturing Dashboard | D10: Dashboard | E10: 30000 | F10: Project
A11: S010 | B11: C0010 | C11: Project Dashboard | D11: Dashboard | E11: 12500 | F11: Project
A12: S011 | B12: C0011 | C12: Invoice Template | D12: Excel | E12: 6500 | F12: Project
A13: S012 | B13: C0012 | C13: Expense Tracker | D13: Excel | E13: 47500 | F13: Project
... A101: S100 | B101: C0100 | C101: Pro Tracker 100 | D101: Dashboard | E101: 53000 | F101: Project

Sheet Invoice
B1: YOUR COMPANY LOGO | F1: INVOICE
B5: Company Name : | C5: =Settings!B3 -> Shivam Analytics | G5: Invoice No | H5: =Settings!B16&"0001" -> INV0001
B6: Address : | C6: =Settings!B9 -> SHIMLA | G6: Date | H6: =TODAY() -> 46247
B7: Phone : | C7: =Settings!B5 -> 9857050777 | G7: Due Date | H7: =TODAY()+30 -> 46277
B8: Email : | C8: =Settings!B6 -> shivamthakur32008@gmail.com
B11: Bill to | C11: C0001
B12: Client Name | C12: =_xlfn.XLOOKUP(C11,client!A:A,client!B:B) -> Summit Enterprises Technologies
B13: Address
B14: Phone | C14: =_xlfn.XLOOKUP(C12,client!B:B,client!D:D) -> 9177777868
B15: Gst | C15: =_xlfn.XLOOKUP(C11,client!A:A,client!G:G) -> 24ABCDE1950F1Z8
B17: Sr | C17: Description | D17: Qty | E17: Unit Price | F17: Tax % | G17: Tax | H17: Total | I17: Notes
B18: =IF(C18="","",1) -> 1 | C18: Sales Dashboard | D18: 1 | E18: =_xlfn.XLOOKUP(C18,Services!C:C,Services!E:E) -> 6000 | F18: =Settings!B15 -> 0.18 | G18: =D18*E18*F18 -> 1080 | H18: =D18*E18+G18 -> 7080
B19: =IF(C19="","",B18+1)
G30: Sub Total | H30: =SUMPRODUCT(D18:D28,E18:E28) -> 6000
G31: Tax | H31: =SUMPRODUCT(G18:G28) -> 1080
G32: Discount | H32: 0
G33: Grand Total | H33: =H30+H31-H32 -> 7080
B35: Payment Details
B36: Bank:
B37: Account :
B38: IFSC :
B39: UPI :

Sheet Invoice_tracker
A1: Client ID | B1: Date | C1: Client Name | D1: Contact Person | E1: Phone | F1: Service | G1: Amount | H1: Status
A2: =Table5[[#This Row],[Client ID]] -> C0001 | B2: 46213 | C2: =client!B2 -> Summit Enterprises Technologies | D2: =Table5[[#This Row],[Contact Person]] -> Harsh Sharma | E2: =Table5[[#This Row],[Phone]] -> 9177777868 | F2: Sales Dashboard | G2: =_xlfn.XLOOKUP(F2,Table6[Service Name],Table6[Unit Price]) -> 6000 | H2: Cancelled
A3: =Table5[[#This Row],[Client ID]] -> C0002 | B3: 46214 | C3: =client!B3 -> Future Solutions LLP | D3: =Table5[[#This Row],[Contact Person]] -> Deepak Mehta | E3: =Table5[[#This Row],[Phone]] -> 9175006691 | F3: Finance Dashboard | G3: =_xlfn.XLOOKUP(F3,Table6[Service Name],Table6[Unit Price]) -> 29500 | H3: Paid | M3: Row Labels | N3: Sum of Amount
A4: =Table5[[#This Row],[Client ID]] -> C0003 | B4: 46215 | C4: =client!B4 -> Zenith Retail Pvt Ltd | D4: =Table5[[#This Row],[Contact Person]] -> Ankit Yadav | E4: =Table5[[#This Row],[Phone]] -> 9525932421 | F4: HR Dashboard | G4: =_xlfn.XLOOKUP(F4,Table6[Service Name],Table6[Unit Price]) -> 17000 | H4: Pending | M4: Jul | N4: 588500
A5: =Table5[[#This Row],[Client ID]] -> C0004 | B5: 46216 | C5: =client!B5 -> Vision Enterprises Enterprises | D5: =Table5[[#This Row],[Contact Person]] -> Neha Yadav | E5: =Table5[[#This Row],[Phone]] -> 9431229838 | F5: Inventory Dashboard | G5: =_xlfn.XLOOKUP(F5,Table6[Service Name],Table6[Unit Price]) -> 45000 | H5: Paid | M5: Aug | N5: 826500
A6: =Table5[[#This Row],[Client ID]] -> C0005 | B6: 46217 | C6: =client!B6 -> Golden Digital LLP | D6: =Table5[[#This Row],[Contact Person]] -> Varun Mishra | E6: =Table5[[#This Row],[Phone]] -> 9167419149 | F6: Marketing Dashboard | G6: =_xlfn.XLOOKUP(F6,Table6[Service Name],Table6[Unit Price]) -> 19000 | H6: Cancelled | M6: Sep | N6: 873000
A7: =Table5[[#This Row],[Client ID]] -> C0006 | B7: 46218 | C7: =client!B7 -> Infinity Exports Works | D7: =Table5[[#This Row],[Contact Person]] -> Riya Yadav | E7: =Table5[[#This Row],[Phone]] -> 9586603020 | F7: Executive Dashboard | G7: =_xlfn.XLOOKUP(F7,Table6[Service Name],Table6[Unit Price]) -> 48000 | H7: Paid | M7: Oct | N7: 809500
A8: =Table5[[#This Row],[Client ID]] -> C0007 | B8: 46219 | C8: =client!B8 -> Vertex Energy India | D8: =Table5[[#This Row],[Contact Person]] -> Sneha Kapoor | E8: =Table5[[#This Row],[Phone]] -> 9468804211 | F8: KPI Dashboard | G8: =_xlfn.XLOOKUP(F8,Table6[Service Name],Table6[Unit Price]) -> 31000 | H8: Pending | M8: Nov | N8: 806000
A9: =Table5[[#This Row],[Client ID]] -> C0008 | B9: 46220 | C9: =client!B9 -> Matrix Manufacturing Corporation | D9: =Table5[[#This Row],[Contact Person]] -> Suresh Gupta | E9: =Table5[[#This Row],[Phone]] -> 9625020128 | F9: Retail Dashboard | G9: =_xlfn.XLOOKUP(F9,Table6[Service Name],Table6[Unit Price]) -> 46500 | H9: Paid | M9: Dec | N9: 410000
A10: =Table5[[#This Row],[Client ID]] -> C0009 | B10: 46221 | C10: =client!B10 -> Dynamic Packaging Solutions | D10: =Table5[[#This Row],[Contact Person]] -> Ankit Reddy | E10: =Table5[[#This Row],[Phone]] -> 9589846746 | F10: Manufacturing Dashboard | G10: =_xlfn.XLOOKUP(F10,Table6[Service Name],Table6[Unit Price]) -> 30000 | H10: Cancelled | M10: Grand Total | N10: 4313500
A11: =Table5[[#This Row],[Client ID]] -> C0010 | B11: 46222 | C11: =client!B11 -> Elite Solutions India | D11: =Table5[[#This Row],[Contact Person]] -> Harsh Yadav | E11: =Table5[[#This Row],[Phone]] -> 9831472844 | F11: Project Dashboard | G11: =_xlfn.XLOOKUP(F11,Table6[Service Name],Table6[Unit Price]) -> 12500 | H11: Paid
A12: =Table5[[#This Row],[Client ID]] -> C0011 | B12: 46223 | C12: =client!B12 -> Nexus Digital Corporation | D12: =Table5[[#This Row],[Contact Person]] -> Divya Verma | E12: =Table5[[#This Row],[Phone]] -> 9630098818 | F12: Invoice Template | G12: =_xlfn.XLOOKUP(F12,Table6[Service Name],Table6[Unit Price]) -> 6500 | H12: Pending
A13: =Table5[[#This Row],[Client ID]] -> C0012 | B13: 46224 | C13: =client!B13 -> Rapid Healthcare Solutions | D13: =Table5[[#This Row],[Contact Person]] -> Priya Gupta | E13: =Table5[[#This Row],[Phone]] -> 9582311296 | F13: Expense Tracker | G13: =_xlfn.XLOOKUP(F13,Table6[Service Name],Table6[Unit Price]) -> 47500 | H13: Paid
A14: =Table5[[#This Row],[Client ID]] -> C0013 | B14: 46225 | C14: =client!B14 -> Titan Foods Technologies | D14: =Table5[[#This Row],[Contact Person]] -> Meera Bansal | E14: =Table5[[#This Row],[Phone]] -> 9508495730 | F14: Budget Planner | G14: =_xlfn.XLOOKUP(F14,Table6[Service Name],Table6[Unit Price]) -> 11500 | H14: Cancelled
A15: =Table5[[#This Row],[Client ID]] -> C0014 | B15: 46226 | C15: =client!B15 -> Royal Infra Group | D15: =Table5[[#This Row],[Contact Person]] -> Amit Kapoor | E15: =Table5[[#This Row],[Phone]] -> 9992379915 | F15: Attendance Tracker | G15: =_xlfn.XLOOKUP(F15,Table6[Service Name],Table6[Unit Price]) -> 5500 | H15: Paid
A16: =Table5[[#This Row],[Client ID]] -> C0015 | B16: 46227 | C16: =client!B16 -> Sky Manufacturing Enterprises | D16: =Table5[[#This Row],[Contact Person]] -> Meera Yadav | E16: =Table5[[#This Row],[Phone]] -> 9708104260 | F16: Payroll Tracker | G16: =_xlfn.XLOOKUP(F16,Table6[Service Name],Table6[Unit Price]) -> 13000 | H16: Pending
A17: =Table5[[#This Row],[Client ID]] -> C0016 | B17: 46228 | C17: =client!B17 -> Blue Services Enterprises | D17: =Table5[[#This Row],[Contact Person]] -> Akash Mehta | E17: =Table5[[#This Row],[Phone]] -> 9528400257 | F17: CRM Tracker | G17: =_xlfn.XLOOKUP(F17,Table6[Service Name],Table6[Unit Price]) -> 31500 | H17: Paid
A18: =Table5[[#This Row],[Client ID]] -> C0017 | B18: 46229 | C18: =client!B18 -> Golden Industries Group | D18: =Table5[[#This Row],[Contact Person]] -> Riya Gupta | E18: =Table5[[#This Row],[Phone]] -> 9218034622 | F18: Quotation Template | G18: =_xlfn.XLOOKUP(F18,Table6[Service Name],Table6[Unit Price]) -> 21500 | H18: Cancelled | M18: Row Labels | N18: Sum of Amount
A19: =Table5[[#This Row],[Client ID]] -> C0018 | B19: 46230 | C19: =client!B19 -> Sky Analytics LLP | D19: =Table5[[#This Row],[Contact Person]] -> Meera Yadav | E19: =Table5[[#This Row],[Phone]] -> 9127381374 | F19: MIS Report | G19: =_xlfn.XLOOKUP(F19,Table6[Service Name],Table6[Unit Price]) -> 17500 | H19: Paid | M19: Everest Traders Solutions | N19: 45000
A20: =Table5[[#This Row],[Client ID]] -> C0019 | B20: 46231 | C20: =client!B20 -> Global Digital Works | D20: =Table5[[#This Row],[Contact Person]] -> Arjun Verma | E20: =Table5[[#This Row],[Phone]] -> 9223859888 | F20: Sales Tracker | G20: =_xlfn.XLOOKUP(F20,Table6[Service Name],Table6[Unit Price]) -> 40000 | H20: Pending | M20: Fusion Engineering Group | N20: 49500
A21: =Table5[[#This Row],[Client ID]] -> C0020 | B21: 46232 | C21: =client!B21 -> Vertex Enterprises LLP | D21: =Table5[[#This Row],[Contact Person]] -> Kavya Jain | E21: =Table5[[#This Row],[Phone]] -> 9894946073 | F21: Purchase Tracker | G21: =_xlfn.XLOOKUP(F21,Table6[Service Name],Table6[Unit Price]) -> 23000 | H21: Paid | M21: Metro Consulting Enterprises | N21: 46000
A22: =Table5[[#This Row],[Client ID]] -> C0021 | B22: 46233 | C22: =client!B22 -> Future Automation Works | D22: =Table5[[#This Row],[Contact Person]] -> Karan Mishra | E22: =Table5[[#This Row],[Phone]] -> 9683226946 | F22: Excel VBA Automation | G22: =_xlfn.XLOOKUP(F22,Table6[Service Name],Table6[Unit Price]) -> 48000 | H22: Cancelled | M22: Titan Infra Technologies | N22: 32500
A23: =Table5[[#This Row],[Client ID]] -> C0022 | B23: 46234 | C23: =client!B23 -> Global Automation Works | D23: =Table5[[#This Row],[Contact Person]] -> Rohit Jain | E23: =Table5[[#This Row],[Phone]] -> 9928862021 | F23: n8n Workflow | G23: =_xlfn.XLOOKUP(F23,Table6[Service Name],Table6[Unit Price]) -> 38500 | H23: Paid | M23: Urban Textiles Works | N23: 44500
A24: =Table5[[#This Row],[Client ID]] -> C0023 | B24: 46235 | C24: =client!B24 -> Royal Packaging Group | D24: =Table5[[#This Row],[Contact Person]] -> Vikas Nair | E24: =Table5[[#This Row],[Phone]] -> 9530231565 | F24: Power Automate Flow | G24: =_xlfn.XLOOKUP(F24,Table6[Service Name],Table6[Unit Price]) -> 49000 | H24: Pending | M24: Grand Total | N24: 217500
A25: =Table5[[#This Row],[Client ID]] -> C0024 | B25: 46236 | C25: =client!B25 -> Everest Digital Pvt Ltd | D25: =Table5[[#This Row],[Contact Person]] -> Amit Reddy | E25: =Table5[[#This Row],[Phone]] -> 9400023374 | F25: Email Automation | G25: =_xlfn.XLOOKUP(F25,Table6[Service Name],Table6[Unit Price]) -> 12500 | H25: Paid
A26: =Table5[[#This Row],[Client ID]] -> C0025 | B26: 46237 | C26: =client!B26 -> Dynamic Digital LLP | D26: =Table5[[#This Row],[Contact Person]] -> Vikas Verma | E26: =Table5[[#This Row],[Phone]] -> 9343573855 | F26: Reporting Automation | G26: =_xlfn.XLOOKUP(F26,Table6[Service Name],Table6[Unit Price]) -> 22500 | H26: Cancelled
A27: =Table5[[#This Row],[Client ID]] -> C0026 | B27: 46238 | C27: =client!B27 -> Apex Electronics Works | D27: =Table5[[#This Row],[Contact Person]] -> Harsh Verma | E27: =Table5[[#This Row],[Phone]] -> 9996197331 | F27: Invoice Automation | G27: =_xlfn.XLOOKUP(F27,Table6[Service Name],Table6[Unit Price]) -> 19500 | H27: Paid
A28: =Table5[[#This Row],[Client ID]] -> C0027 | B28: 46239 | C28: =client!B28 -> Silver Manufacturing Works | D28: =Table5[[#This Row],[Contact Person]] -> Priya Reddy | E28: =Table5[[#This Row],[Phone]] -> 9875053406 | F28: File Automation | G28: =_xlfn.XLOOKUP(F28,Table6[Service Name],Table6[Unit Price]) -> 23500 | H28: Pending | M28: Row Labels | N28: Sum of Amount
A29: =Table5[[#This Row],[Client ID]] -> C0028 | B29: 46240 | C29: =client!B29 -> Green Enterprises Pvt Ltd | D29: =Table5[[#This Row],[Contact Person]] -> Karan Yadav | E29: =Table5[[#This Row],[Phone]] -> 9599669927 | F29: Data Automation | G29: =_xlfn.XLOOKUP(F29,Table6[Service Name],Table6[Unit Price]) -> 38000 | H29: Paid | M29: Paid | N29: 283500 | P29: =N30+N31 -> 126500
A30: =Table5[[#This Row],[Client ID]] -> C0029 | B30: 46241 | C30: =client!B30 -> Titan Analytics Corporation | D30: =Table5[[#This Row],[Contact Person]] -> Amit Sharma | E30: =Table5[[#This Row],[Phone]] -> 9958303050 | F30: API Integration | G30: =_xlfn.XLOOKUP(F30,Table6[Service Name],Table6[Unit Price]) -> 16500 | H30: Cancelled | M30: Cancelled | N30: 69000
A31: =Table5[[#This Row],[Client ID]] -> C0030 | B31: 46242 | C31: =client!B31 -> Infinity Consulting Group | D31: =Table5[[#This Row],[Contact Person]] -> Amit Singh | E31: =Table5[[#This Row],[Phone]] -> 9328470563 | F31: Workflow Automation | G31: =_xlfn.XLOOKUP(F31,Table6[Service Name],Table6[Unit Price]) -> 12500 | H31: Paid | M31: Pending | N31: 57500
A32: =Table5[[#This Row],[Client ID]] -> C0031 | B32: 46243 | C32: =client!B32 -> NextGen Manufacturing Corporation | D32: =Table5[[#This Row],[Contact Person]] -> Rahul Joshi | E32: =Table5[[#This Row],[Phone]] -> 9894485254 | F32: Power BI Sales | G32: =_xlfn.XLOOKUP(F32,Table6[Service Name],Table6[Unit Price]) -> 45500 | H32: Pending | M32: Grand Total | N32: 410000
A33: =Table5[[#This Row],[Client ID]] -> C0032 | B33: 46244 | C33: =client!B33 -> Matrix Enterprises Enterprises | D33: =Table5[[#This Row],[Contact Person]] -> Karan Agarwal | E33: =Table5[[#This Row],[Phone]] -> 9648195686 | F33: Power BI Finance | G33: =_xlfn.XLOOKUP(F33,Table6[Service Name],Table6[Unit Price]) -> 17500 | H33: Paid
A34: =Table5[[#This Row],[Client ID]] -> C0033 | B34: 46245 | C34: =client!B34 -> Apex Exports Corporation | D34: =Table5[[#This Row],[Contact Person]] -> Rohit Gupta | E34: =Table5[[#This Row],[Phone]] -> 9608409165 | F34: Power BI HR | G34: =_xlfn.XLOOKUP(F34,Table6[Service Name],Table6[Unit Price]) -> 28000 | H34: Cancelled
A35: =Table5[[#This Row],[Client ID]] -> C0034 | B35: 46246 | C35: =client!B35 -> Core Automation Enterprises | D35: =Table5[[#This Row],[Contact Person]] -> Arjun Reddy | E35: =Table5[[#This Row],[Phone]] -> 9933749898 | F35: Power BI Inventory | G35: =_xlfn.XLOOKUP(F35,Table6[Service Name],Table6[Unit Price]) -> 5000 | H35: Paid
A36: =Table5[[#This Row],[Client ID]] -> C0035 | B36: 46247 | C36: =client!B36 -> Golden Foods Pvt Ltd | D36: =Table5[[#This Row],[Contact Person]] -> Neha Agarwal | E36: =Table5[[#This Row],[Phone]] -> 9585520203 | F36: Power BI Executive | G36: =_xlfn.XLOOKUP(F36,Table6[Service Name],Table6[Unit Price]) -> 23500 | H36: Pending | J36: Row Labels | K36: Sum of Amount | M36: Row Labels | N36: Sum of Amount
A37: =Table5[[#This Row],[Client ID]] -> C0036 | B37: 46248 | C37: =client!B37 -> Matrix Packaging Enterprises | D37: =Table5[[#This Row],[Contact Person]] -> Anjali Mishra | E37: =Table5[[#This Row],[Phone]] -> 9397625709 | F37: Power BI Marketing | G37: =_xlfn.XLOOKUP(F37,Table6[Service Name],Table6[Unit Price]) -> 27000 | H37: Paid | J37: Balance Sheet Model | K37: 14500 | M37: Asset Register | N37: 45000
A38: =Table5[[#This Row],[Client ID]] -> C0037 | B38: 46249 | C38: =client!B38 -> Smart Pharma Enterprises | D38: =Table5[[#This Row],[Contact Person]] -> Pooja Joshi | E38: =Table5[[#This Row],[Phone]] -> 9700773368 | F38: Power BI Operations | G38: =_xlfn.XLOOKUP(F38,Table6[Service Name],Table6[Unit Price]) -> 12500 | H38: Cancelled | J38: GST Report | K38: 12500 | M38: Dispatch Tracker | N38: 44500
A39: =Table5[[#This Row],[Client ID]] -> C0038 | B39: 46250 | C39: =client!B39 -> Zenith Healthcare Solutions | D39: =Table5[[#This Row],[Contact Person]] -> Suresh Verma | E39: =Table5[[#This Row],[Phone]] -> 9820647678 | F39: Power BI Procurement | G39: =_xlfn.XLOOKUP(F39,Table6[Service Name],Table6[Unit Price]) -> 44000 | H39: Paid | J39: Purchase Register | K39: 10000 | M39: P&L Report | N39: 49500
A40: =Table5[[#This Row],[Client ID]] -> C0039 | B40: 46251 | C40: =client!B40 -> Zenith Exports Corporation | D40: =Table5[[#This Row],[Contact Person]] -> Aditya Bansal | E40: =Table5[[#This Row],[Phone]] -> 9808945035 | F40: Power BI CRM | G40: =_xlfn.XLOOKUP(F40,Table6[Service Name],Table6[Unit Price]) -> 21500 | H40: Pending | J40: Stock Ageing | K40: 5000 | M40: Variance Analysis | N40: 32500
...

Sheet Dashboard
B2: Invoice Command Centre
